<?xml version="1.0" encoding="utf-8"?><testsuites><testsuite name="pytest" errors="2" failures="0" skipped="0" tests="2" time="4.050" timestamp="2022-04-03T15:39:55.804317" hostname="eli.local"><testcase classname="" name="tests.api.test_sources" time="0.000"><error message="collection failure">tests/api/test_sources.py:7: in &lt;module&gt;
    from django.contrib.auth import models
../../.pyenv/versions/3.9.0/envs/autosa-back/lib/python3.9/site-packages/django/contrib/auth/models.py:3: in &lt;module&gt;
    from django.contrib.auth.base_user import AbstractBaseUser, BaseUserManager
../../.pyenv/versions/3.9.0/envs/autosa-back/lib/python3.9/site-packages/django/contrib/auth/base_user.py:49: in &lt;module&gt;
    class AbstractBaseUser(models.Model):
../../.pyenv/versions/3.9.0/envs/autosa-back/lib/python3.9/site-packages/django/db/models/base.py:127: in __new__
    app_config = apps.get_containing_app_config(module)
../../.pyenv/versions/3.9.0/envs/autosa-back/lib/python3.9/site-packages/django/apps/registry.py:260: in get_containing_app_config
    self.check_apps_ready()
../../.pyenv/versions/3.9.0/envs/autosa-back/lib/python3.9/site-packages/django/apps/registry.py:137: in check_apps_ready
    settings.INSTALLED_APPS
../../.pyenv/versions/3.9.0/envs/autosa-back/lib/python3.9/site-packages/django/conf/__init__.py:87: in __getattr__
    self._setup(name)
../../.pyenv/versions/3.9.0/envs/autosa-back/lib/python3.9/site-packages/django/conf/__init__.py:67: in _setup
    raise ImproperlyConfigured(
E   django.core.exceptions.ImproperlyConfigured: Requested setting INSTALLED_APPS, but settings are not configured. You must either define the environment variable DJANGO_SETTINGS_MODULE or call settings.configure() before accessing settings.</error></testcase><testcase classname="" name="tests.infotools.test_location_parsing" time="0.000"><error message="collection failure">ImportError while importing test module '/Users/irinatruong/src/autoSA-backend/tests/infotools/test_location_parsing.py'.
Hint: make sure your test modules/packages have valid Python names.
Traceback:
../../.pyenv/versions/3.9.0/lib/python3.9/importlib/__init__.py:127: in import_module
    return _bootstrap._gcd_import(name[level:], package, level)
tests/infotools/test_location_parsing.py:5: in &lt;module&gt;
    from infotools.location_parsing import extract_locations_for_dataframe
E   ModuleNotFoundError: No module named 'infotools'</error></testcase></testsuite></testsuites>